Workbook

Sheet HOLDING_02_2026
A1: HOLDING – MZDY ÚNOR 2026
A2: Konsolidovaný pohled přes VZC + KERA. Většina buněk je napojená na zdrojové listy v tomto souboru.
A4: Společnost | B4: Jméno | C4: Pozice | D4: Pracoviště | E4: Prac.dnů | F4: Odpracováno | G4: Přesčasy | H4: Dovolená | I4: Termín dov. | J4: Nemoc | K4: Termín nem. | L4: OČR | M4: Termín OČR | N4: Základ | O4: Os.ohod. | P4: DPP | Q4: §10 | R4: Kafeterie | S4: Parkovné | T4: Multisport | U4: Obědy | V4: Srážka | W4: Obrat pro osobko | X4: CEO_ONLY | Y4: Pozn. | Z4: Zdroj
A5: VZC | B5: ='VZC_01_2026'!A4 | C5: ='VZC_01_2026'!B4 | D5: ='VZC_01_2026'!C4 | E5: ='VZC_01_2026'!D4 | F5: ='VZC_01_2026'!E4 | G5: ='VZC_01_2026'!F4 | H5: ='VZC_01_2026'!G4 | I5: ='VZC_01_2026'!H4 | ... K5: ='VZC_01_2026'!J4 | N5: ='VZC_01_2026'!K4 | O5: ='VZC_01_2026'!L4 | P5: ='VZC_01_2026'!M4 | Q5: ='VZC_01_2026'!N4 | R5: ='VZC_01_2026'!O4 | S5: ='VZC_01_2026'!P4 | T5: ='VZC_01_2026'!Q4 | U5: ='VZC_01_2026'!R4 | X5: ='VZC_01_2026'!S4 | Y5: ='VZC_01_2026'!T4 | Z5: VZC_01_2026!4
A6: VZC | B6: ='VZC_01_2026'!A5 | C6: ='VZC_01_2026'!B5 | D6: ='VZC_01_2026'!C5 | E6: ='VZC_01_2026'!D5 | F6: ='VZC_01_2026'!E5 | G6: ='VZC_01_2026'!F5 | H6: ='VZC_01_2026'!G5 | I6: ='VZC_01_2026'!H5 | ... K6: ='VZC_01_2026'!J5 | N6: ='VZC_01_2026'!K5 | O6: ='VZC_01_2026'!L5 | P6: ='VZC_01_2026'!M5 | Q6: ='VZC_01_2026'!N5 | R6: ='VZC_01_2026'!O5 | S6: ='VZC_01_2026'!P5 | T6: ='VZC_01_2026'!Q5 | U6: ='VZC_01_2026'!R5 | X6: ='VZC_01_2026'!S5 | Y6: ='VZC_01_2026'!T5 | Z6: VZC_01_2026!5
A7: VZC | B7: ='VZC_01_2026'!A6 | C7: ='VZC_01_2026'!B6 | D7: ='VZC_01_2026'!C6 | E7: ='VZC_01_2026'!D6 | F7: ='VZC_01_2026'!E6 | G7: ='VZC_01_2026'!F6 | H7: ='VZC_01_2026'!G6 | I7: ='VZC_01_2026'!H6 | ... K7: ='VZC_01_2026'!J6 | N7: ='VZC_01_2026'!K6 | O7: ='VZC_01_2026'!L6 | P7: ='VZC_01_2026'!M6 | Q7: ='VZC_01_2026'!N6 | R7: ='VZC_01_2026'!O6 | S7: ='VZC_01_2026'!P6 | T7: ='VZC_01_2026'!Q6 | U7: ='VZC_01_2026'!R6 | X7: ='VZC_01_2026'!S6 | Y7: ='VZC_01_2026'!T6 | Z7: VZC_01_2026!6
A8: VZC | B8: ='VZC_01_2026'!A7 | C8: ='VZC_01_2026'!B7 | D8: ='VZC_01_2026'!C7 | E8: ='VZC_01_2026'!D7 | F8: ='VZC_01_2026'!E7 | G8: ='VZC_01_2026'!F7 | H8: ='VZC_01_2026'!G7 | I8: ='VZC_01_2026'!H7 | ... K8: ='VZC_01_2026'!J7 | N8: ='VZC_01_2026'!K7 | O8: ='VZC_01_2026'!L7 | P8: ='VZC_01_2026'!M7 | Q8: ='VZC_01_2026'!N7 | R8: ='VZC_01_2026'!O7 | S8: ='VZC_01_2026'!P7 | T8: ='VZC_01_2026'!Q7 | U8: ='VZC_01_2026'!R7 | X8: ='VZC_01_2026'!S7 | Y8: ='VZC_01_2026'!T7 | Z8: VZC_01_2026!7
A9: VZC | B9: ='VZC_01_2026'!A8 | C9: ='VZC_01_2026'!B8 | D9: ='VZC_01_2026'!C8 | E9: ='VZC_01_2026'!D8 | F9: ='VZC_01_2026'!E8 | G9: ='VZC_01_2026'!F8 | H9: ='VZC_01_2026'!G8 | I9: ='VZC_01_2026'!H8 | ... K9: ='VZC_01_2026'!J8 | N9: ='VZC_01_2026'!K8 | O9: ='VZC_01_2026'!L8 | P9: ='VZC_01_2026'!M8 | Q9: ='VZC_01_2026'!N8 | R9: ='VZC_01_2026'!O8 | S9: ='VZC_01_2026'!P8 | T9: ='VZC_01_2026'!Q8 | U9: ='VZC_01_2026'!R8 | X9: ='VZC_01_2026'!S8 | Y9: ='VZC_01_2026'!T8 | Z9: VZC_01_2026!8
A10: VZC | B10: ='VZC_01_2026'!A9 | C10: ='VZC_01_2026'!B9 | D10: ='VZC_01_2026'!C9 | E10: ='VZC_01_2026'!D9 | F10: ='VZC_01_2026'!E9 | G10: ='VZC_01_2026'!F9 | H10: ='VZC_01_2026'!G9 | I10: ='VZC_01_2026'!H9 | ... K10: ='VZC_01_2026'!J9 | N10: ='VZC_01_2026'!K9 | O10: ='VZC_01_2026'!L9 | P10: ='VZC_01_2026'!M9 | Q10: ='VZC_01_2026'!N9 | R10: ='VZC_01_2026'!O9 | S10: ='VZC_01_2026'!P9 | T10: ='VZC_01_2026'!Q9 | U10: ='VZC_01_2026'!R9 | X10: ='VZC_01_2026'!S9 | Y10: ='VZC_01_2026'!T9 | Z10: VZC_01_2026!9
A11: VZC | B11: ='VZC_01_2026'!A10 | C11: ='VZC_01_2026'!B10 | D11: ='VZC_01_2026'!C10 | E11: ='VZC_01_2026'!D10 | F11: ='VZC_01_2026'!E10 | G11: ='VZC_01_2026'!F10 | H11: ='VZC_01_2026'!G10 | I11: ='VZC_01_2026'!H10 | ... K11: ='VZC_01_2026'!J10 | N11: ='VZC_01_2026'!K10 | O11: ='VZC_01_2026'!L10 | P11: ='VZC_01_2026'!M10 | Q11: ='VZC_01_2026'!N10 | R11: ='VZC_01_2026'!O10 | S11: ='VZC_01_2026'!P10 | T11: ='VZC_01_2026'!Q10 | U11: ='VZC_01_2026'!R10 | X11: ='VZC_01_2026'!S10 | Y11: ='VZC_01_2026'!T10 | Z11: VZC_01_2026!10
A12: VZC | B12: ='VZC_01_2026'!A11 | C12: ='VZC_01_2026'!B11 | D12: ='VZC_01_2026'!C11 | E12: ='VZC_01_2026'!D11 | F12: ='VZC_01_2026'!E11 | G12: ='VZC_01_2026'!F11 | H12: ='VZC_01_2026'!G11 | I12: ='VZC_01_2026'!H11 | ... K12: ='VZC_01_2026'!J11 | N12: ='VZC_01_2026'!K11 | O12: ='VZC_01_2026'!L11 | P12: ='VZC_01_2026'!M11 | Q12: ='VZC_01_2026'!N11 | R12: ='VZC_01_2026'!O11 | S12: ='VZC_01_2026'!P11 | T12: ='VZC_01_2026'!Q11 | U12: ='VZC_01_2026'!R11 | X12: ='VZC_01_2026'!S11 | Y12: ='VZC_01_2026'!T11 | Z12: VZC_01_2026!11
A13: VZC | B13: ='VZC_01_2026'!A12 | C13: ='VZC_01_2026'!B12 | D13: ='VZC_01_2026'!C12 | E13: ='VZC_01_2026'!D12 | F13: ='VZC_01_2026'!E12 | G13: ='VZC_01_2026'!F12 | H13: ='VZC_01_2026'!G12 | I13: ='VZC_01_2026'!H12 | ... K13: ='VZC_01_2026'!J12 | N13: ='VZC_01_2026'!K12 | O13: ='VZC_01_2026'!L12 | P13: ='VZC_01_2026'!M12 | Q13: ='VZC_01_2026'!N12 | R13: ='VZC_01_2026'!O12 | S13: ='VZC_01_2026'!P12 | T13: ='VZC_01_2026'!Q12 | U13: ='VZC_01_2026'!R12 | X13: ='VZC_01_2026'!S12 | Y13: ='VZC_01_2026'!T12 | Z13: VZC_01_2026!12
A14: VZC | B14: ='VZC_01_2026'!A13 | C14: ='VZC_01_2026'!B13 | D14: ='VZC_01_2026'!C13 | E14: ='VZC_01_2026'!D13 | F14: ='VZC_01_2026'!E13 | G14: ='VZC_01_2026'!F13 | H14: ='VZC_01_2026'!G13 | I14: ='VZC_01_2026'!H13 | ... K14: ='VZC_01_2026'!J13 | N14: ='VZC_01_2026'!K13 | O14: ='VZC_01_2026'!L13 | P14: ='VZC_01_2026'!M13 | Q14: ='VZC_01_2026'!N13 | R14: ='VZC_01_2026'!O13 | S14: ='VZC_01_2026'!P13 | T14: ='VZC_01_2026'!Q13 | U14: ='VZC_01_2026'!R13 | X14: ='VZC_01_2026'!S13 | Y14: ='VZC_01_2026'!T13 | Z14: VZC_01_2026!13
A15: VZC | B15: ='VZC_01_2026'!A14 | C15: ='VZC_01_2026'!B14 | D15: ='VZC_01_2026'!C14 | E15: ='VZC_01_2026'!D14 | F15: ='VZC_01_2026'!E14 | G15: ='VZC_01_2026'!F14 | H15: ='VZC_01_2026'!G14 | I15: ='VZC_01_2026'!H14 | ... K15: ='VZC_01_2026'!J14 | N15: ='VZC_01_2026'!K14 | O15: ='VZC_01_2026'!L14 | P15: ='VZC_01_2026'!M14 | Q15: ='VZC_01_2026'!N14 | R15: ='VZC_01_2026'!O14 | S15: ='VZC_01_2026'!P14 | T15: ='VZC_01_2026'!Q14 | U15: ='VZC_01_2026'!R14 | X15: ='VZC_01_2026'!S14 | Y15: ='VZC_01_2026'!T14 | Z15: VZC_01_2026!14
A16: VZC | B16: ='VZC_01_2026'!A15 | C16: ='VZC_01_2026'!B15 | D16: ='VZC_01_2026'!C15 | E16: ='VZC_01_2026'!D15 | F16: ='VZC_01_2026'!E15 | G16: ='VZC_01_2026'!F15 | H16: ='VZC_01_2026'!G15 | I16: ='VZC_01_2026'!H15 | ... K16: ='VZC_01_2026'!J15 | N16: ='VZC_01_2026'!K15 | O16: ='VZC_01_2026'!L15 | P16: ='VZC_01_2026'!M15 | Q16: ='VZC_01_2026'!N15 | R16: ='VZC_01_2026'!O15 | S16: ='VZC_01_2026'!P15 | T16: ='VZC_01_2026'!Q15 | U16: ='VZC_01_2026'!R15 | X16: ='VZC_01_2026'!S15 | Y16: ='VZC_01_2026'!T15 | Z16: VZC_01_2026!15
... A66: VZC | B66: ='VZC_01_2026'!A65 | C66: ='VZC_01_2026'!B65 | D66: ='VZC_01_2026'!C65 | E66: ='VZC_01_2026'!D65 | F66: ='VZC_01_2026'!E65 | G66: ='VZC_01_2026'!F65 | H66: ='VZC_01_2026'!G65 | I66: ='VZC_01_2026'!H65 | ... K66: ='VZC_01_2026'!J65 | N66: ='VZC_01_2026'!K65 | O66: ='VZC_01_2026'!L65 | P66: ='VZC_01_2026'!M65 | Q66: ='VZC_01_2026'!N65 | R66: ='VZC_01_2026'!O65 | S66: ='VZC_01_2026'!P65 | T66: ='VZC_01_2026'!Q65 | U66: ='VZC_01_2026'!R65 | X66: ='VZC_01_2026'!S65 | Y66: ='VZC_01_2026'!T65 | Z66: VZC_01_2026!65
A67: KERA | B67: ='KERA_02_2026'!A4 | C67: ='KERA_02_2026'!B4 | D67: KERA | E67: ='KERA_02_2026'!C4 | F67: ='KERA_02_2026'!D4 | G67: ='KERA_02_2026'!E4 | H67: ='KERA_02_2026'!F4 | I67: ='KERA_02_2026'!G4 | J67: ='KERA_02_2026'!H4 | K67: ='KERA_02_2026'!I4 | L67: ='KERA_02_2026'!J4 | ... S67: ='KERA_02_2026'!Q4 | U67: ='KERA_02_2026'!R4 | V67: ='KERA_02_2026'!S4 | W67: ='KERA_02_2026'!U4 | X67: ='KERA_02_2026'!T4 | Z67: KERA_02_2026!4
A68: KERA | B68: ='KERA_02_2026'!A5 | C68: ='KERA_02_2026'!B5 | D68: KERA | E68: ='KERA_02_2026'!C5 | F68: ='KERA_02_2026'!D5 | G68: ='KERA_02_2026'!E5 | H68: ='KERA_02_2026'!F5 | I68: ='KERA_02_2026'!G5 | J68: ='KERA_02_2026'!H5 | K68: ='KERA_02_2026'!I5 | L68: ='KERA_02_2026'!J5 | ... S68: ='KERA_02_2026'!Q5 | U68: ='KERA_02_2026'!R5 | V68: ='KERA_02_2026'!S5 | W68: ='KERA_02_2026'!U5 | X68: ='KERA_02_2026'!T5 | Z68: KERA_02_2026!5
A69: KERA | B69: ='KERA_02_2026'!A6 | C69: ='KERA_02_2026'!B6 | D69: KERA | E69: ='KERA_02_2026'!C6 | F69: ='KERA_02_2026'!D6 | G69: ='KERA_02_2026'!E6 | H69: ='KERA_02_2026'!F6 | I69: ='KERA_02_2026'!G6 | J69: ='KERA_02_2026'!H6 | K69: ='KERA_02_2026'!I6 | L69: ='KERA_02_2026'!J6 | ... S69: ='KERA_02_2026'!Q6 | U69: ='KERA_02_2026'!R6 | V69: ='KERA_02_2026'!S6 | W69: ='KERA_02_2026'!U6 | X69: ='KERA_02_2026'!T6 | Z69: KERA_02_2026!6
A70: KERA | B70: ='KERA_02_2026'!A7 | C70: ='KERA_02_2026'!B7 | D70: KERA | E70: ='KERA_02_2026'!C7 | F70: ='KERA_02_2026'!D7 | G70: ='KERA_02_2026'!E7 | H70: ='KERA_02_2026'!F7 | I70: ='KERA_02_2026'!G7 | J70: ='KERA_02_2026'!H7 | K70: ='KERA_02_2026'!I7 | L70: ='KERA_02_2026'!J7 | ... S70: ='KERA_02_2026'!Q7 | U70: ='KERA_02_2026'!R7 | V70: ='KERA_02_2026'!S7 | W70: ='KERA_02_2026'!U7 | X70: ='KERA_02_2026'!T7 | Z70: KERA_02_2026!7
A71: KERA | B71: ='KERA_02_2026'!A8 | C71: ='KERA_02_2026'!B8 | D71: KERA | E71: ='KERA_02_2026'!C8 | F71: ='KERA_02_2026'!D8 | G71: ='KERA_02_2026'!E8 | H71: ='KERA_02_2026'!F8 | I71: ='KERA_02_2026'!G8 | J71: ='KERA_02_2026'!H8 | K71: ='KERA_02_2026'!I8 | L71: ='KERA_02_2026'!J8 | ... S71: ='KERA_02_2026'!Q8 | U71: ='KERA_02_2026'!R8 | V71: ='KERA_02_2026'!S8 | W71: ='KERA_02_2026'!U8 | X71: ='KERA_02_2026'!T8 | Z71: KERA_02_2026!8
A72: KERA | B72: ='KERA_02_2026'!A9 | C72: ='KERA_02_2026'!B9 | D72: KERA | E72: ='KERA_02_2026'!C9 | F72: ='KERA_02_2026'!D9 | G72: ='KERA_02_2026'!E9 | H72: ='KERA_02_2026'!F9 | I72: ='KERA_02_2026'!G9 | J72: ='KERA_02_2026'!H9 | K72: ='KERA_02_2026'!I9 | L72: ='KERA_02_2026'!J9 | ... S72: ='KERA_02_2026'!Q9 | U72: ='KERA_02_2026'!R9 | V72: ='KERA_02_2026'!S9 | W72: ='KERA_02_2026'!U9 | X72: ='KERA_02_2026'!T9 | Z72: KERA_02_2026!9
A73: KERA | B73: ='KERA_02_2026'!A10 | C73: ='KERA_02_2026'!B10 | D73: KERA | E73: ='KERA_02_2026'!C10 | F73: ='KERA_02_2026'!D10 | G73: ='KERA_02_2026'!E10 | H73: ='KERA_02_2026'!F10 | I73: ='KERA_02_2026'!G10 | J73: ='KERA_02_2026'!H10 | K73: ='KERA_02_2026'!I10 | L73: ='KERA_02_2026'!J10 | ... S73: ='KERA_02_2026'!Q10 | U73: ='KERA_02_2026'!R10 | V73: ='KERA_02_2026'!S10 | W73: ='KERA_02_2026'!U10 | X73: ='KERA_02_2026'!T10 | Z73: KERA_02_2026!10
A74: KERA | B74: ='KERA_02_2026'!A11 | C74: ='KERA_02_2026'!B11 | D74: KERA | E74: ='KERA_02_2026'!C11 | F74: ='KERA_02_2026'!D11 | G74: ='KERA_02_2026'!E11 | H74: ='KERA_02_2026'!F11 | I74: ='KERA_02_2026'!G11 | J74: ='KERA_02_2026'!H11 | K74: ='KERA_02_2026'!I11 | L74: ='KERA_02_2026'!J11 | ... S74: ='KERA_02_2026'!Q11 | U74: ='KERA_02_2026'!R11 | V74: ='KERA_02_2026'!S11 | W74: ='KERA_02_2026'!U11 | X74: ='KERA_02_2026'!T11 | Z74: KERA_02_2026!11
A75: KERA | B75: ='KERA_02_2026'!A12 | C75: ='KERA_02_2026'!B12 | D75: KERA | E75: ='KERA_02_2026'!C12 | F75: ='KERA_02_2026'!D12 | G75: ='KERA_02_2026'!E12 | H75: ='KERA_02_2026'!F12 | I75: ='KERA_02_2026'!G12 | J75: ='KERA_02_2026'!H12 | K75: ='KERA_02_2026'!I12 | L75: ='KERA_02_2026'!J12 | ... S75: ='KERA_02_2026'!Q12 | U75: ='KERA_02_2026'!R12 | V75: ='KERA_02_2026'!S12 | W75: ='KERA_02_2026'!U12 | X75: ='KERA_02_2026'!T12 | Z75: KERA_02_2026!12
A76: KERA | B76: ='KERA_02_2026'!A13 | C76: ='KERA_02_2026'!B13 | D76: KERA | E76: ='KERA_02_2026'!C13 | F76: ='KERA_02_2026'!D13 | G76: ='KERA_02_2026'!E13 | H76: ='KERA_02_2026'!F13 | I76: ='KERA_02_2026'!G13 | J76: ='KERA_02_2026'!H13 | K76: ='KERA_02_2026'!I13 | L76: ='KERA_02_2026'!J13 | ... S76: ='KERA_02_2026'!Q13 | U76: ='KERA_02_2026'!R13 | V76: ='KERA_02_2026'!S13 | W76: ='KERA_02_2026'!U13 | X76: ='KERA_02_2026'!T13 | Z76: KERA_02_2026!13
A77: KERA | B77: ='KERA_02_2026'!A14 | C77: ='KERA_02_2026'!B14 | D77: KERA | E77: ='KERA_02_2026'!C14 | F77: ='KERA_02_2026'!D14 | G77: ='KERA_02_2026'!E14 | H77: ='KERA_02_2026'!F14 | I77: ='KERA_02_2026'!G14 | J77: ='KERA_02_2026'!H14 | K77: ='KERA_02_2026'!I14 | L77: ='KERA_02_2026'!J14 | ... S77: ='KERA_02_2026'!Q14 | U77: ='KERA_02_2026'!R14 | V77: ='KERA_02_2026'!S14 | W77: ='KERA_02_2026'!U14 | X77: ='KERA_02_2026'!T14 | Z77: KERA_02_2026!14
A78: KERA | B78: ='KERA_02_2026'!A15 | C78: ='KERA_02_2026'!B15 | D78: KERA | E78: ='KERA_02_2026'!C15 | F78: ='KERA_02_2026'!D15 | G78: ='KERA_02_2026'!E15 | H78: ='KERA_02_2026'!F15 | I78: ='KERA_02_2026'!G15 | J78: ='KERA_02_2026'!H15 | K78: ='KERA_02_2026'!I15 | L78: ='KERA_02_2026'!J15 | ... S78: ='KERA_02_2026'!Q15 | U78: ='KERA_02_2026'!R15 | V78: ='KERA_02_2026'!S15 | W78: ='KERA_02_2026'!U15 | X78: ='KERA_02_2026'!T15 | Z78: KERA_02_2026!15
... A86: KERA | B86: ='KERA_02_2026'!A23 | C86: ='KERA_02_2026'!B23 | D86: KERA | E86: ='KERA_02_2026'!C23 | F86: ='KERA_02_2026'!D23 | G86: ='KERA_02_2026'!E23 | H86: ='KERA_02_2026'!F23 | I86: ='KERA_02_2026'!G23 | J86: ='KERA_02_2026'!H23 | K86: ='KERA_02_2026'!I23 | L86: ='KERA_02_2026'!J23 | ... S86: ='KERA_02_2026'!Q23 | U86: ='KERA_02_2026'!R23 | V86: ='KERA_02_2026'!S23 | W86: ='KERA_02_2026'!U23 | X86: ='KERA_02_2026'!T23 | Z86: KERA_02_2026!23

Sheet HOLDING_SOUHRN
A1: HOLDING – souhrn
A3: Ukazatel | B3: Hodnota
A4: Počet řádků celkem | B4: =COUNTA('HOLDING_02_2026'!B5:B86)
A5: Počet řádků VZC | B5: =COUNTIF('HOLDING_02_2026'!A5:A86,"VZC")
A6: Počet řádků KERA | B6: =COUNTIF('HOLDING_02_2026'!A5:A86,"KERA")
A8: Řádky s obratem pro osobko | B8: =COUNTIF('HOLDING_02_2026'!W5:W86,">0")

Sheet VZC_01_2026
A1: VZC - MZDY ÚNOR 2026
A2: 🟧 Oranžová = CEO_ONLY (rodina) | 🟨 Šedá = MD
A3: Jméno | B3: Pozice | C3: Pracoviště | D3: Prac.dnů | E3: Odpracováno | F3: Přesčasy | G3: Dovolená | H3: Termín dov. | I3: Nemoc | J3: Termín nem. | K3: Základ | L3: Os.ohod. | M3: DPP | N3: §10 | O3: Kafeterie | P3: Parkovné | Q3: Multisport | R3: Obědy | S3: CEO_ONLY | T3: Pozn.
A4: Baloghová Pavla | B4: DH | C4: Ústí | D4: 20 | E4: 18 | G4: 16 | H4: 24.-25.2. | K4: 35000 | M4: 11990 | O4: 100 | P4: 500
A5: Bilynska Nataliya | B5: EXT | C5: VZC | M5: 11990 | R5: 200
A6: Buts Sergei | B6: Lékař | C6: Ústí | D6: 20 | E6: 20 | K6: 35000 | M6: 11990 | O6: 100 | P6: 500
A7: Codreanu Corina | B7: ADM | C7: VZC | K7: 21000 | M7: 11990
A8: Codreanu Nicolae | B8: Lékař | C8: Louny | D8: 20 | E8: 20 | K8: 30000 | M8: 11990 | Q8: 485
A9: Čáka Jan | B9: ADM | C9: VZC | M9: 11990 | S9: ANO
A10: Čáka Josef | B10: ADM | C10: VZC | M10: 11990 | S10: ANO
A11: Čáková Miluše | B11: ADM | C11: VZC | D11: 20 | M11: 11990 | S11: ANO
A12: Čáková Veronika | B12: ADM | C12: VZC | M12: 11990 | S12: ANO
A13: Čmudová Radka | B13: Sestra | C13: Louny | D13: 20 | E13: 17 | G13: 24 | H13: 16.-17.2., 20.2. | K13: 25000 | M13: 11990
A14: Davidová Lenka | B14: Sestra | C14: Ústí | D14: 20 | E14: 15 | I14: 40 | J14: OČR: 2.-10.2.; od 9.2. v práci | M14: 11990 | O14: 100 | P14: 375
A15: Dávidová Zuzana | B15: Recepční | C15: Ústí | D15: 20 | E15: 19 | G15: 8 | H15: 20.2. | K15: 25000 | M15: 11990 | O15: 50 | R15: 2460
A16: Farkašová Lucie | B16: EXT | C16: Ústí | D16: 20 | M16: 11990 | R16: 200
A17: Havlena Barbora | B17: DH | C17: Louny | D17: 20 | E17: 18 | G17: 16 | H17: 26.-27.2. | K17: 30000 | M17: 11990
A18: Hlaváčková Lýdie | B18: Sestra | C18: Ústí | D18: 20 | E18: 12 | G18: 64 | H18: 5.-16.2. | K18: 24100 | M18: 11990 | O18: 100 | P18: 375 | R18: 1155
A19: Ivanov Sergei | B19: Lékař | C19: Ústí | D19: 20 | E19: 18 | G19: 16 | H19: 2.-3.2. | K19: 35000 | M19: 11990 | O19: 100 | P19: 375 | Q19: 485 | R19: 2635
A20: Jeřábková Lucie | B20: Sestra | C20: Ústí | D20: 20 | E20: 18 | G20: 16 | H20: 9.-10.2. | K20: 24100 | L20: 8000 | M20: 11990 | O20: 50 | R20: 1018
A21: Kačírková Jaroslava | B21: Sestra | C21: Ústí | D21: 20 | E21: 20 | K21: 28000 | M21: 11990 | O21: 100 | Q21: 485 | R21: 784
A22: Komjáti Tamás | B22: Zubní lékař | C22: Louny | D22: 20 | E22: 18 | G22: 16 | H22: 5.-6.2. | K22: 100000 | L22: 140000 | M22: 11990 | T22: Bere si hypotéku
A23: Kramářová Tereza | B23: Sestra | C23: Ústí | D23: 20 | E23: 0 | I23: 160 | J23: 1.-28.2. | K23: 28000 | M23: 11990
A24: Kronychová Tereza | B24: EXT | C24: VZC | M24: 11990
A25: Kuziv Michaela | B25: Provozní manažer | C25: VZC | D25: 20 | E25: 12 | G25: 64 | H25: 5.-16.2. | K25: 30000 | L25: 10000 | M25: 11990 | O25: 100 | R25: 543
A26: Lazareva Lylia | B26: EXT | C26: VZC | D26: 20 | M26: 11990 | Q26: 485
A27: Leixnerová Irena | B27: Recepční | C27: VZC | K27: 22000 | M27: 11990
A28: Linhartová Denisa | B28: Recepční | C28: Louny | D28: 20 | E28: 20 | F28: 15 | K28: 22000 | M28: 11990 | R28: 200
A29: Linhartová Jiřina | B29: Recepční | C29: Louny | D29: 20 | M29: 11990
A30: Lipčáková Alice | B30: Recepční | C30: VZC | D30: 20 | E30: MD
A31: Maekeová Kateřina | B31: DH | C31: Ústí | D31: 20 | E31: 20 | K31: 30000 | M31: 11990 | O31: 100 | P31: 375
A32: Mayer Pavla | B32: Recepční | C32: VZC | D32: 20 | E32: 20 | O32: 100 | R32: 1018
A33: Mudrová Natálie | B33: Sestra | C33: Ústí | D33: 20 | E33: MD | M33: 11990
A34: Neffe Irena | B34: Lékař | C34: Ústí | D34: 20 | K34: 30000 | M34: 11990
A35: Nováčková Lucie | B35: Sestra | C35: VZC | D35: 20 | E35: 20 | K35: 25000 | M35: 7500
A36: Nováčková Věra | B36: Lékař | C36: Louny | D36: 20 | M36: 11990
A37: Nykodymová Alexandra | B37: EXT | C37: Louny | D37: 20 | F37: 29 | M37: 11990 | R37: 200
A38: Obr Jan | B38: EXT | C38: VZC | M38: 11990
A39: Obr Pavel | B39: EXT | C39: VZC | D39: 20 | M39: 7000
A40: Parkhomenko Artem | B40: Lékař | C40: Louny | D40: 20 | E40: 18 | G40: 16 | H40: 16.-17.2. | K40: 30000 | M40: 11990
...

Sheet LOUNY_01_2026
A1: VZC Louny s.r.o. - MZDY ÚNOR 2026
A2: 🟧 Oranžová = CEO_ONLY (rodina) | 🟨 Šedá = MD
A3: Jméno | B3: Pozice | C3: Pracoviště | D3: Prac.dnů | E3: Odpracováno | F3: Přesčasy | G3: Dovolená | H3: Termín dov. | I3: Nemoc | J3: Termín nem. | K3: Základ | L3: Os.ohod. | M3: DPP | N3: §10 | O3: Kafeterie | P3: Parkovné | Q3: Multisport | R3: Obědy | S3: CEO_ONLY | T3: Pozn.
A4: Baloghová Pavla | B4: DH | C4: VZC
A5: Bilynska Nataliya | B5: EXT | C5: VZC
A6: Buts Sergei | B6: Lékař | C6: VZC | M6: 11990
A7: Codreanu Corina | B7: ADM | C7: VZC | M7: 11990
A8: Codreanu Nicolae | B8: Lékař | C8: VZC | M8: 11990
A9: Čáka Jan | B9: ADM | C9: VZC | M9: 11990
A10: Čáka Josef | B10: ADM | C10: VZC | M10: 11990
A11: Čáková Miluše | B11: ADM | C11: VZC | M11: 11990
A12: Čáková Veronika | B12: ADM | C12: VZC | M12: 11990
A13: Čmudová Radka | B13: Sestra | C13: VZC | M13: 11990
A14: Davidová Lenka | B14: Sestra | C14: VZC | M14: 11990
A15: Dávidová Zuzana | B15: Recepční | C15: VZC
A16: Farkašová Lucie | B16: EXT | C16: VZC | M16: 11990
A17: Havlena Barbora | B17: DH | C17: VZC | M17: 11990
A18: Hlaváčková Lýdie | B18: Sestra | C18: VZC
A19: Ivanov Sergei | B19: Lékař | C19: VZC | M19: 11990
A20: Jeřábková Lucie | B20: Sestra | C20: VZC
A21: Kačírková Jaroslava | B21: Sestra | C21: VZC
A22: Komjáti Tamás | B22: Zubní lékař | C22: VZC | M22: 11990
A23: Kramářová Tereza | B23: Sestra | C23: VZC
A24: Kronychová Tereza | B24: EXT | C24: VZC | M24: 11990
A25: Kuziv Michaela | B25: Provozní manažer | C25: VZC | M25: 7500
A26: Lazareva Lylia | B26: EXT | C26: VZC | M26: 11990
A27: Leixnerová Irena | B27: Recepční | C27: VZC
A28: Linhartová Denisa | B28: Recepční | C28: VZC | M28: 11990
A29: Linhartová Jiřina | B29: Recepční | C29: VZC
A30: Lipčáková Alice | B30: Recepční | C30: VZC
A31: Maekeová Kateřina | B31: DH | C31: VZC | M31: 11990
A32: Mayer Pavla | B32: Recepční | C32: VZC
A33: Mudrová Natálie | B33: Sestra | C33: VZC
A34: Neffe Irena | B34: Lékař | C34: VZC | M34: 11990
A35: Nováčková Lucie | B35: Sestra | C35: VZC
A36: Nováčková Věra | B36: Lékař | C36: VZC | M36: 11990
A37: Nykodymová Alexandra | B37: EXT | C37: VZC | M37: 11990
A38: Obr Jan | B38: EXT | C38: VZC
A39: Obr Pavel | B39: EXT | C39: VZC
A40: Parkhomenko Artem | B40: Lékař | C40: VZC | M40: 11990
...

Sheet ÚSTÍ_01_2026
A1: VZC Ústí - MZDY ÚNOR 2026
A2: 🟧 Oranžová = CEO_ONLY (rodina) | 🟨 Šedá = MD
A3: Jméno | B3: Pozice | C3: Pracoviště | D3: Prac.dnů | E3: Odpracováno | F3: Přesčasy | G3: Dovolená | H3: Termín dov. | I3: Nemoc | J3: Termín nem. | K3: Základ | L3: Os.ohod. | M3: DPP | N3: §10 | O3: Kafeterie | P3: Parkovné | Q3: Multisport | R3: Obědy | S3: CEO_ONLY | T3: Pozn.
A4: Baloghová Pavla | B4: DH | C4: VZC
A5: Bilynska Nataliya | B5: EXT | C5: VZC
A6: Buts Sergei | B6: Lékař | C6: VZC | M6: 11990
A7: Codreanu Corina | B7: ADM | C7: VZC | M7: 11990
A8: Codreanu Nicolae | B8: Lékař | C8: VZC | M8: 11990
A9: Čáka Jan | B9: ADM | C9: VZC | M9: 11990
A10: Čáka Josef | B10: ADM | C10: VZC | M10: 11990
A11: Čáková Miluše | B11: ADM | C11: VZC | M11: 11990
A12: Čáková Veronika | B12: ADM | C12: VZC | M12: 11990
A13: Čmudová Radka | B13: Sestra | C13: VZC
A14: Davidová Lenka | B14: Sestra | C14: VZC
A15: Dávidová Zuzana | B15: Recepční | C15: VZC
A16: Farkašová Lucie | B16: EXT | C16: VZC | M16: 11990
A17: Havlena Barbora | B17: DH | C17: VZC | M17: 11990
A18: Hlaváčková Lýdie | B18: Sestra | C18: VZC | M18: 11990
A19: Ivanov Sergei | B19: Lékař | C19: VZC | M19: 11990
A20: Jeřábková Lucie | B20: Sestra | C20: VZC
A21: Kačírková Jaroslava | B21: Sestra | C21: VZC
A22: Komjáti Tamás | B22: Zubní lékař | C22: VZC | M22: 11990
A23: Kramářová Tereza | B23: Sestra | C23: VZC
A24: Kronychová Tereza | B24: EXT | C24: VZC
A25: Kuziv Michaela | B25: Provozní manažer | C25: VZC | M25: 7500
A26: Lazareva Lylia | B26: EXT | C26: VZC | M26: 11990
A27: Leixnerová Irena | B27: Recepční | C27: VZC
A28: Linhartová Denisa | B28: Recepční | C28: VZC
A29: Linhartová Jiřina | B29: Recepční | C29: VZC
A30: Lipčáková Alice | B30: Recepční | C30: VZC
A31: Maekeová Kateřina | B31: DH | C31: VZC | M31: 11990
A32: Mayer Pavla | B32: Recepční | C32: VZC
A33: Mudrová Natálie | B33: Sestra | C33: VZC
A34: Neffe Irena | B34: Lékař | C34: VZC | M34: 11990
A35: Nováčková Lucie | B35: Sestra | C35: VZC
A36: Nováčková Věra | B36: Lékař | C36: VZC | M36: 11990
A37: Nykodymová Alexandra | B37: EXT | C37: VZC | M37: 11990
A38: Obr Jan | B38: EXT | C38: VZC
A39: Obr Pavel | B39: EXT | C39: VZC
A40: Parkhomenko Artem | B40: Lékař | C40: VZC | M40: 11990
...

Sheet VARIABILNÍ_INFO
A1: VARIABILNÍ SLOŽKY - TYPY A NASTAVENÍ
A4: TYP | B4: POPIS | C4: PŘÍKLAD VÝPOČTU | D4: KDE NASTAVIT
A5: Z OBRATU | B5: % z hrubého obratu nad stanovený práh | C5: Obrat 150 000, Práh 110 000, Sazba 25% → (150000-110000) × 0.25 = 10 000 Kč | D5: Sloupec Práh/Sazba: "110000/25%"
A6: PROVIZE | B6: % z konkrétního výkonu/prodeje | C6: Tržby 50 000 × 10% = 5 000 Kč | D6: Sloupec Práh/Sazba: "10%"
A7: BONUS | B7: Jednorázová částka za splnění cíle | C7: Splněn kvartální cíl = 15 000 Kč | D7: Sloupec Var.popis: popis cíle

Sheet EXPORT_MANAŽERKA
A1: DOCHÁZKA - EXPORT (ÚNOR 2026 | vše do matky VZC | BEZ CEO_ONLY, BEZ MEZD)
A2: ⚠️ Neobsahuje: rodinu Čáka, rodinu Vyšata, Polákovou, Vacha, osoby na MD
A4: Spol. | B4: Jméno | C4: Pozice | D4: Pracoviště | E4: Prac.dnů | F4: Odpracováno | G4: Dovolená | H4: Nemoc | I4: Přesčasy | J4: Poznámky
A5: VZC | B5: Baloghová Pavla | C5: DH | D5: Ústí | E5: 20 | F5: 18 | G5: 16 | J5: Dov: 24.-25.2.
A6: VZC | B6: Bilynska Nataliya | C6: EXT | D6: VZC
A7: VZC | B7: Buts Sergei | D7: Ústí | E7: 20 | F7: 20
A8: VZC | B8: Čáková Miluše | C8: ADM | D8: VZC | E8: 20
A9: VZC | B9: Čmudová Radka | C9: Sestra | D9: Louny | E9: 20 | F9: 17 | G9: 24 | J9: Dov: 16.-17.2., 20.2.
A10: VZC | B10: Codreanu Nicolae | C10: Lékař | D10: Louny | E10: 20 | F10: 20
A11: VZC | B11: Davidová Lenka | C11: Sestra | D11: Ústí | E11: 20 | F11: 15 | J11: OČR 40 h: 2.-10.2.; od 9.2. v práci
A12: VZC | B12: Dávidová Zuzana | C12: Recepční | D12: Ústí | E12: 20 | F12: 19 | G12: 8 | J12: Dov: 20.2. | DOPLNIT ČÁSTKY
A13: VZC | B13: Farkašová Lucie | C13: EXT | D13: Ústí | E13: 20
A14: VZC | B14: Havlena Barbora | C14: DH | D14: Louny | E14: 20 | F14: 18 | G14: 16 | J14: Dov: 26.-27.2.
A15: VZC | B15: Hlaváčková Lýdie | C15: Sestra | D15: Ústí | E15: 20 | F15: 12 | G15: 64 | J15: Dov: 5.-16.2.
A16: VZC | B16: Ibragimov Firdavs | D16: Ústí | E16: 20 | F16: 19 | G16: 8 | J16: Dov: 9.2.
A17: VZC | B17: Ivanov Sergei | C17: Lékař | D17: Ústí | E17: 20 | F17: 18 | G17: 16 | J17: Dov: 2.-3.2.
A18: VZC | B18: Jeřábková Lucie | C18: Sestra | D18: Ústí | E18: 20 | F18: 18 | G18: 16 | J18: Dov: 9.-10.2.
A19: VZC | B19: Kačírková Jaroslava | C19: Sestra | D19: Ústí | E19: 20 | F19: 20
A20: VZC | B20: Komjáti Tamás | C20: Lékař | D20: Louny | E20: 20 | F20: 18 | G20: 16 | J20: Dov: 5.-6.2.
A21: VZC | B21: Kramářová Tereza | C21: Sestra | D21: Ústí | E21: 20 | F21: 0 | H21: 160 | J21: Nem: 1.-28.2.
A22: VZC | B22: Kuziv Michaela | C22: Provozní manažer | D22: VZC | E22: 20 | F22: 12 | G22: 64 | J22: Dov: 5.-16.2.
A23: VZC | B23: Lazareva Lylia | C23: EXT | D23: VZC | E23: 20
A24: VZC | B24: Linhartová Denisa | C24: Recepční | D24: Louny | E24: 20 | F24: 20 | I24: 15
A25: VZC | B25: Linhartová Jiřina | C25: Recepční | D25: Louny | E25: 20
A26: VZC | B26: Maekeová Kateřina | C26: DH | D26: Ústí | E26: 20 | F26: 20 | J26: OČR 1.2. = víkend
A27: VZC | B27: Mayer Pavla | C27: Recepce | D27: VZC | E27: 20 | F27: 20
A28: VZC | B28: Neffe Irena | C28: Lékař | D28: Ústí | E28: 20
A29: VZC | B29: Nováčková Lucie | C29: Sestra | D29: VZC | E29: 20 | F29: 20
A30: VZC | B30: Nováčková Věra | C30: Lékař | D30: Louny | E30: 20
A31: VZC | B31: Nykodymová Alexandra | C31: EXT | D31: Louny | E31: 20 | I31: 29
A32: VZC | B32: Obr Pavel | C32: EXT | D32: VZC | E32: 20
A33: VZC | B33: Parkhomenko Artem | C33: Lékař | D33: Louny | E33: 20 | F33: 18 | G33: 16 | J33: Dov: 16.-17.2.
A34: VZC | B34: Parkhomenko Olga | C34: ADM | D34: Louny | E34: 20
A35: VZC | B35: Pecháčková Kristýna | C35: Sestra | D35: Ústí | E35: 20 | F35: 20
A36: VZC | B36: Poluzina Maria | C36: EXT | D36: VZC | E36: 20
A37: VZC | B37: Šafaříková Martina | C37: EXT | D37: VZC | E37: 20
A38: VZC | B38: Šafaříková Sabina | C38: DH | D38: Ústí | E38: 20 | F38: 8 | H38: 96 | J38: Nem: 2.-17.2.; 16.-17. již byla v práci, ale PN pokračovala
A39: VZC | B39: Šedová Valentýna | C39: EXT | D39: VZC | E39: 20
A40: VZC | B40: Sémová Petra | C40: Sestra | D40: Louny | E40: 20 | F40: 20 | I40: 10
A41: VZC | B41: Serhejev Serhij | C41: Lékař | D41: Louny | E41: 20 | F41: 20
...

Sheet NASTAVENÍ_NEXUS
A1: ⚙️ NEXUS - SYSTÉMOVÉ NASTAVENÍ
A3: SPOLEČNOSTI
A4: ID | B4: Kód | C4: Název | D4: IČO
A5: COMP001 | B5: INVESTIMENTI | C5: INVESTIMENTI s.r.o. | D5: 14336642
A6: COMP002 | B6: VZC | C6: VZC s.r.o. | D6: 04084471
A7: COMP003 | B7: VZC-LN | C7: VZC Louny s.r.o. | D7: 21825742
A8: COMP004 | B8: VZC-UL | C8: VZC Ústí n.L. s.r.o. | D8: 21825769
A9: COMP005 | B9: KERA | C9: KERA-DENS s.r.o. | D9: 61536300
A10: COMP006 | B10: LOGPACK | C10: LOGPACK, s.r.o. | D10: 05822041
A12: PRACOVIŠTĚ
A13: ID | B13: Kód | C13: Název | D13: Společnost
A14: LOC001 | B14: USTI | C14: VZC Ústí nad Labem | D14: VZC-UL
A15: LOC002 | B15: LOUNY | C15: VZC Louny | D15: VZC-LN
A16: LOC003 | B16: VZC | C16: VZC Centrála | D16: VZC
A17: LOC004 | B17: KERA | C17: KERA-DENS Laboratoř | D17: KERA
A20: VARIABILNÍ SLOŽKY
A21: Kód | B21: Název | C21: Popis | D21: Vzorec
A22: Z OBRATU | B22: Dopočet z obratu | C22: % z hrubého obratu nad práh | D22: MAX(0, (Obrat - Práh) × %)
A23: PROVIZE | B23: Provize | C23: % z konkrétního výkonu | D23: Výkon × %
A24: BONUS | B24: Bonus | C24: Jednorázová částka | D24: Pevná částka
A28: ROLE A OPRÁVNĚNÍ
A29: Role | B29: Vidí tarify | C29: Vidí CEO_ONLY | D29: Schvaluje | E29: Exportuje
A30: CEO | B30: ANO | C30: ANO | D30: ANO | E30: ANO
A31: Partner | B31: Svá divize | C31: NE | D31: Svá divize | E31: NE
A32: HR | B32: ANO | C32: NE | D32: NE | E32: ANO
A33: Vedoucí | B33: NE | C33: NE | D33: Svůj tým | E33: NE
A34: Zaměstnanec | B34: NE | C34: NE | D34: NE | E34: NE
A36: BENEFITY - KATALOG
A37: Kód | B37: Název | C37: Typ | D37: Default hodnota | E37: Popis
A38: STRAV | B38: Stravenky | C38: Nepeněžní | D38: 120 Kč/den | E38: Stravenky - hodnota za pracovní den
A39: MULTI | B39: Multisport | C39: Nepeněžní | D39: 485 Kč/měs | E39: Multisport karta - měsíční příspěvek
A40: KAFET | B40: Kafeterie | C40: Srážka | D40: 50-100 Kč/měs | E40: Benefit program - srážka ze mzdy
A41: PARK | B41: Parkovné | C41: Srážka | D41: 375-500 Kč/měs | E41: Parkovací místo - srážka ze mzdy
A42: OBEDY | B42: Obědy | C42: Srážka | D42: Dle spotřeby | E42: Závodní stravování - srážka

Sheet KATALOG_POZIC
A1: ⚙️ NEXUS - KATALOG PRACOVNÍCH POZIC
A2: Každá pozice může mít: HPP + DPP + Ostatní + Nepeněžní plnění | Variabilní složky s default nastavením | Katalog je rozšiřitelný
A3: ZÁKLADNÍ INFO | G3: ÚVAZKY | J3: VARIABILNÍ SLOŽKA | N3: BENEFITY (default) | R3: SYSTÉM
A4: ID | B4: Kód | C4: Název CZ | D4: Název EN | E4: Kategorie | F4: Společnost | G4: HPP | H4: DPP | I4: DPČ | J4: Variabilní typ | K4: Var. % | L4: Práh | M4: Do hrubé | N4: Stravenky | O4: Multisport | P4: Kafeterie | Q4: Parkovné | R4: Oprávnění | S4: Popis
A5: POS001 | B5: LEK | C5: Lékař | D5: Dentist | E5: Zdravotnictví | F5: VZC | G5: ANO | H5: ANO | I5: NE | J5: Z OBRATU | K5: 0.25 | L5: 110000 | M5: ANO | N5: 120 | O5: 485 | P5: 100 | Q5: 500 | R5: Zaměstnanec | S5: Zubní lékař - stomatolog
A6: POS002 | B6: ZUB-LEK | C6: Zubní lékař | D6: Dental Surgeon | E6: Zdravotnictví | F6: VZC | G6: ANO | H6: ANO | I6: NE | J6: Z OBRATU | K6: 0.25 | L6: 110000 | M6: ANO | N6: 120 | O6: 485 | P6: 100 | Q6: 500 | R6: Zaměstnanec | S6: Specializovaný zubní lékař
A7: POS003 | B7: DH | C7: Dentální hygienistka | D7: Dental Hygienist | E7: Zdravotnictví | F7: VZC | G7: ANO | H7: ANO | I7: NE | J7: Z OBRATU | K7: 0.2 | L7: 80000 | M7: ANO | N7: 120 | O7: 485 | P7: 100 | Q7: 500 | R7: Zaměstnanec | S7: Dentální hygiena
A8: POS004 | B8: SES | C8: Sestra | D8: Dental Nurse | E8: Zdravotnictví | F8: VZC | G8: ANO | H8: ANO | I8: NE | K8: 0 | L8: 0 | N8: 120 | O8: 485 | P8: 100 | Q8: 375 | R8: Zaměstnanec | S8: Dentální sestra / asistentka
A9: POS005 | B9: REC | C9: Recepční | D9: Receptionist | E9: Administrativa | F9: VZC | G9: ANO | H9: ANO | I9: NE | K9: 0 | L9: 0 | N9: 120 | O9: 485 | P9: 50 | Q9: 375 | R9: Zaměstnanec | S9: Recepce kliniky
A10: POS006 | B10: ADM | C10: Administrativa | D10: Administration | E10: Administrativa | F10: VZC+KERA | G10: ANO | H10: ANO | I10: ANO | K10: 0 | L10: 0 | N10: 120 | O10: 0 | P10: 100 | Q10: 375 | R10: Zaměstnanec | S10: Administrativní pracovník
A11: POS007 | B11: PM | C11: Provozní manažer | D11: Operations Manager | E11: Management | F11: VZC | G11: ANO | H11: ANO | I11: NE | J11: BONUS | K11: 0 | L11: 0 | M11: ANO | N11: 120 | O11: 485 | P11: 100 | Q11: 500 | R11: Vedoucí | S11: Vedení provozu kliniky
A12: POS008 | B12: TECH | C12: Technik | D12: Dental Technician | E12: Výroba | F12: KERA | G12: ANO | H12: ANO | I12: NE | K12: 0 | L12: 0 | N12: 120 | O12: 0 | P12: 100 | Q12: 375 | R12: Zaměstnanec | S12: Zubní technik - laboratoř
A13: POS009 | B13: ZUB-TECH | C13: Zubní technik | D13: Dental Lab Technician | E13: Výroba | F13: KERA | G13: ANO | H13: ANO | I13: NE | K13: 0 | L13: 0 | N13: 120 | O13: 0 | P13: 100 | Q13: 375 | R13: Zaměstnanec | S13: Zubní technik - specializace
A14: POS010 | B14: VED-LAB | C14: Vedoucí laboratoře | D14: Lab Manager | E14: Management | F14: KERA | G14: ANO | H14: ANO | I14: NE | J14: BONUS | K14: 0 | L14: 0 | M14: ANO | N14: 120 | O14: 0 | P14: 100 | Q14: 375 | R14: Vedoucí | S14: Vedení zubní laboratoře
A15: POS011 | B15: ROZ | C15: Rozvoz | D15: Delivery Driver | E15: Logistika | F15: KERA | G15: ANO | H15: ANO | I15: NE | K15: 0 | L15: 0 | N15: 120 | O15: 0 | P15: 50 | Q15: 0 | R15: Zaměstnanec | S15: Rozvoz zakázek
A16: POS012 | B16: EXT | C16: Externí spolupracovník | D16: External Contractor | E16: Externí | F16: VZC+KERA | G16: NE | H16: ANO | I16: ANO | J16: PROVIZE | K16: 0.1 | L16: 0 | M16: NE | N16: 0 | O16: 0 | P16: 0 | Q16: 0 | R16: Zaměstnanec | S16: DPP / DPČ / Externí
A17: POS013 | B17: CEO | C17: Jednatel | D17: CEO | E17: Management | F17: HOLDING | G17: ANO | H17: ANO | I17: NE | K17: 0 | L17: 0 | N17: 0 | O17: 0 | P17: 0 | Q17: 0 | R17: CEO | S17: Jednatel společnosti
A18: POS014 | B18: PART | C18: Partner | D18: Partner | E18: Management | F18: HOLDING | G18: ANO | H18: ANO | I18: NE | K18: 0 | L18: 0 | N18: 0 | O18: 0 | P18: 0 | Q18: 0 | R18: Partner | S18: Společník
A19: POS015 | B19: HR | C19: HR / Mzdy | D19: HR Manager | E19: Management | F19: HOLDING | G19: ANO | H19: ANO | I19: NE | K19: 0 | L19: 0 | N19: 120 | O19: 485 | P19: 100 | Q19: 375 | R19: HR | S19: Lidské zdroje a mzdy
A20: POS016 | K20: 0 | L20: 0 | N20: 0 | O20: 0 | P20: 0 | Q20: 0
A21: POS017 | K21: 0 | L21: 0 | N21: 0 | O21: 0 | P21: 0 | Q21: 0
A22: POS018 | K22: 0 | L22: 0 | N22: 0 | O22: 0 | P22: 0 | Q22: 0
A23: POS019 | K23: 0 | L23: 0 | N23: 0 | O23: 0 | P23: 0 | Q23: 0
A24: POS020 | K24: 0 | L24: 0 | N24: 0 | O24: 0 | P24: 0 | Q24: 0

Sheet KERA_02_2026
A1: KERA-DENS - MZDY ÚNOR 2026
A2: 🟧 Oranžová = CEO_ONLY (rodina) | U2: Vyplň jen tam, kde se osobko počítá z obratu.
A3: Jméno | B3: Pozice | C3: Prac.dnů | D3: Odpracováno | E3: Přesčasy | F3: Dovolená | G3: Termín dov. | H3: Nemoc | I3: Termín nem. | J3: OČR | K3: Termín OČR | L3: Základ | M3: Os.ohod. | N3: DPP | O3: §10 | P3: Kafeterie | Q3: Parkovné | R3: Obědy | S3: Srážka | T3: CEO_ONLY | U3: Obrat pro osobko
A4: Aron Andrea | B4: Technik | C4: 20 | D4: MD | N4: 11990
A5: Čáka Jan | B5: ADM | C5: 20 | N5: 11990 | T5: ANO
A6: Čáka Josef | B6: ADM | C6: 20 | N6: 11990 | T6: ANO
A7: Čáková Miluše | B7: ADM | N7: 11990 | T7: ANO
A8: Čáková Veronika | B8: ADM | N8: 11990 | T8: ANO
A9: Drncová Aneta | B9: rozvoz | C9: 20 | D9: MD | L9: 25000 | M9: 5000 | N9: 5000
A10: Horová Zdeňka | B10: Technik | C10: 20 | D10: 19 | H10: 8 | I10: POHŘEB 25.2. | L10: 24100 | N10: 11990 | P10: 100 | R10: 1406
A11: Kadlecová Renata | B11: Technik | C11: 20 | D11: 18 | F11: 16 | G11: 13.-16.2. | L11: 24100 | M11: =IF(U11="","",MAX(0,(U11-72000)*25%)) | P11: 50 | R11: 1940
A12: Limberková Šárka | B12: Technik | C12: 20 | D12: 19 | F12: 8 | G12: 04.02. | L12: 28000 | M12: =IF(U12="","",MAX(0,(U12-74000)*25%)) | N12: 3000 | P12: 100 | R12: 1886
A13: Maraske Jan | B13: Technik | C13: 20 | D13: 20 | L13: 30000 | P13: 100
A14: Plachký Jan | B14: Vedoucí laboratoře | C14: 20 | D14: 19 | H14: 8 | I14: Lékař - doprovod 6.2.2026 | L14: 30000 | M14: 15000 | N14: 5000 | Q14: 375
A15: Poláková Eva | B15: ADM | C15: 20 | N15: 11990 | T15: ANO
A16: Řeháková Miroslava | B16: ADM | C16: 20 | N16: 11990
A17: Vodvářková Karla | B17: Technik | C17: 20 | D17: 19 | F17: 8 | G17: 26.2. | L17: 35000 | M17: =IF(U17="","",MAX(0,(U17-92000)*25%)) | P17: 100 | Q17: 375 | R17: 2266
A18: Vyšata Filip | B18: ADM | C18: 20 | N18: 11990 | T18: ANO
A19: Vyšatová Petra | B19: ADM | C19: 20 | N19: 11990 | T19: ANO
A20: Vyšatová Viktorie | B20: ADM | N20: 11990 | T20: ANO
A21: Žigová Barbora | B21: EXT | C21: 20 | D21: 19 | F21: 8 | G21: 20.2. | L21: 30000 | M21: 7000 | N21: 11990 | P21: 50 | Q21: 500
A22: Surmová Marcela | B22: rozvoz | C22: 20 | D22: 16 | H22: 32 | I22: 18.-20.2.=PN, 25.2.= lékař | L22: 25000 | N22: 5000 | P22: 100 | Q22: 375
A23: Rost Jakub | B23: EXT | C23: 20

Sheet KERA_KONTROLA
A1: Kontrola importu docházky
A3: Položka | B3: Hodnota
A4: Zdrojových řádků | B4: 17
A5: Doplněno / spárováno | B5: 17
A7: Nejednoznačná nebo ručně spárovaná jména
A8: Zdroj | B8: Cíl v mzdovém souboru | C8: Typ párování
A9: Miloslava Řeháková | B9: Řeháková Miroslava | C9: manual_alias
A12: Pravidla osobního ohodnocení (doplněno)
A13: Jméno | B13: Pravidlo | C13: Poznámka
A14: Limberková Šárka | B14: 25 % z obratu nad 74 000 Kč | C14: Os.ohod. v hlavním listu ponecháno prázdné do doplnění obratu.
A15: Vodvářková Karla | B15: 25 % z obratu nad 92 000 Kč | C15: Os.ohod. v hlavním listu ponecháno prázdné do doplnění obratu.
A16: Kadlecová Renata | B16: 25 % z obratu nad 72 000 Kč | C16: Os.ohod. v hlavním listu ponecháno prázdné do doplnění obratu.
A18: Nově přidán vstup pro obrat
A19: Sloupec | B19: Použití | C19: Týká se
A20: U = Obrat pro osobko | B20: Po vyplnění se Os.ohod. spočítá automaticky | C20: Kadlecová, Limberková, Vodvářková
